[2017-05-28 23:49:32,495: WARNING/MainProcess] /home/cabox/workspace/CyclopsVFX-Polyphemus/local/lib/python3.4/site-packages/kombu/pidbox.py:71: UserWarning: A node named worker1@box-codeanywhere is already using this process mailbox!

Maybe you forgot to shutdown the other node or did not do so properly?
Or if you meant to start multiple nodes on the same host please make sure
you give each node a unique node name!

  warnings.warn(W_PIDBOX_IN_USE.format(node=self))
[2017-05-29 00:18:07,134: WARNING/MainProcess] /home/cabox/workspace/CyclopsVFX-Polyphemus/local/lib/python3.4/site-packages/kombu/pidbox.py:71: UserWarning: A node named worker1@box-codeanywhere is already using this process mailbox!

Maybe you forgot to shutdown the other node or did not do so properly?
Or if you meant to start multiple nodes on the same host please make sure
you give each node a unique node name!

  warnings.warn(W_PIDBOX_IN_USE.format(node=self))
[2017-05-29 00:21:00,990: WARNING/MainProcess] consumer: Connection to broker lost. Trying to re-establish the connection...
Traceback (most recent call last):
  File "/home/cabox/workspace/CyclopsVFX-Polyphemus/local/lib/python3.4/site-packages/celery/worker/consumer/consumer.py", line 318, in start
    blueprint.start(self)
  File "/home/cabox/workspace/CyclopsVFX-Polyphemus/local/lib/python3.4/site-packages/celery/bootsteps.py", line 119, in start
    step.start(parent)
  File "/home/cabox/workspace/CyclopsVFX-Polyphemus/local/lib/python3.4/site-packages/celery/worker/consumer/consumer.py", line 594, in start
    c.loop(*c.loop_args())
  File "/home/cabox/workspace/CyclopsVFX-Polyphemus/local/lib/python3.4/site-packages/celery/worker/loops.py", line 88, in asynloop
    next(loop)
  File "/home/cabox/workspace/CyclopsVFX-Polyphemus/local/lib/python3.4/site-packages/kombu/async/hub.py", line 345, in create_loop
    cb(*cbargs)
  File "/home/cabox/workspace/CyclopsVFX-Polyphemus/local/lib/python3.4/site-packages/kombu/transport/base.py", line 236, in on_readable
    reader(loop)
  File "/home/cabox/workspace/CyclopsVFX-Polyphemus/local/lib/python3.4/site-packages/kombu/transport/base.py", line 218, in _read
    drain_events(timeout=0)
  File "/home/cabox/workspace/CyclopsVFX-Polyphemus/local/lib/python3.4/site-packages/amqp/connection.py", line 464, in drain_events
    return self.blocking_read(timeout)
  File "/home/cabox/workspace/CyclopsVFX-Polyphemus/local/lib/python3.4/site-packages/amqp/connection.py", line 469, in blocking_read
    return self.on_inbound_frame(frame)
  File "/home/cabox/workspace/CyclopsVFX-Polyphemus/local/lib/python3.4/site-packages/amqp/method_framing.py", line 68, in on_frame
    callback(channel, method_sig, buf, None)
  File "/home/cabox/workspace/CyclopsVFX-Polyphemus/local/lib/python3.4/site-packages/amqp/connection.py", line 473, in on_inbound_method
    method_sig, payload, content,
  File "/home/cabox/workspace/CyclopsVFX-Polyphemus/local/lib/python3.4/site-packages/amqp/abstract_channel.py", line 142, in dispatch_method
    listener(*args)
  File "/home/cabox/workspace/CyclopsVFX-Polyphemus/local/lib/python3.4/site-packages/amqp/connection.py", line 593, in _on_close
    self._x_close_ok()
  File "/home/cabox/workspace/CyclopsVFX-Polyphemus/local/lib/python3.4/site-packages/amqp/connection.py", line 608, in _x_close_ok
    self.send_method(spec.Connection.CloseOk, callback=self._on_close_ok)
  File "/home/cabox/workspace/CyclopsVFX-Polyphemus/local/lib/python3.4/site-packages/amqp/abstract_channel.py", line 64, in send_method
    conn.frame_writer(1, self.channel_id, sig, args, content)
  File "/home/cabox/workspace/CyclopsVFX-Polyphemus/local/lib/python3.4/site-packages/amqp/method_framing.py", line 174, in write_frame
    write(view[:offset])
  File "/home/cabox/workspace/CyclopsVFX-Polyphemus/local/lib/python3.4/site-packages/amqp/transport.py", line 269, in write
    self._write(s)
ConnectionResetError: [Errno 104] Connection reset by peer
[2017-05-29 00:21:01,151: ERROR/MainProcess] consumer: Cannot connect to amqp://guest:**@127.0.0.1:5672//: [Errno 111] Connection refused.
Trying again in 2.00 seconds...

[2017-05-29 00:21:03,195: ERROR/MainProcess] consumer: Cannot connect to amqp://guest:**@127.0.0.1:5672//: [Errno 111] Connection refused.
Trying again in 4.00 seconds...

